Failure # 1 (occurred at 2023-02-24_16-35-30)
Traceback (most recent call last):
  File "/home/mbwie001/.local/lib/python3.8/site-packages/ray/tune/execution/ray_trial_executor.py", line 1070, in get_next_executor_event
    future_result = ray.get(ready_future)
  File "/home/mbwie001/.local/lib/python3.8/site-packages/ray/_private/client_mode_hook.py", line 105, in wrapper
    return func(*args, **kwargs)
  File "/home/mbwie001/.local/lib/python3.8/site-packages/ray/_private/worker.py", line 2311, in get
    raise value
  File "python/ray/_raylet.pyx", line 1135, in ray._raylet.task_execution_handler
  File "python/ray/_raylet.pyx", line 1045, in ray._raylet.execute_task_with_cancellation_handler
  File "python/ray/_raylet.pyx", line 782, in ray._raylet.execute_task
  File "python/ray/_raylet.pyx", line 945, in ray._raylet.execute_task
  File "python/ray/_raylet.pyx", line 599, in ray._raylet.store_task_errors
ray.exceptions.RayActorError: The actor died because of an error raised in its creation task, [36mray::A3C.__init__()[39m (pid=27527, ip=10.8.13.207, repr=A3C)
  File "/home/mbwie001/.local/lib/python3.8/site-packages/ray/rllib/algorithms/algorithm.py", line 441, in __init__
    super().__init__(
  File "/home/mbwie001/.local/lib/python3.8/site-packages/ray/tune/trainable/trainable.py", line 169, in __init__
    self.setup(copy.deepcopy(self.config))
  File "/home/mbwie001/.local/lib/python3.8/site-packages/ray/rllib/algorithms/algorithm.py", line 566, in setup
    self.workers = WorkerSet(
  File "/home/mbwie001/.local/lib/python3.8/site-packages/ray/rllib/evaluation/worker_set.py", line 191, in __init__
    raise e.args[0].args[2]
  File "/home/mbwie001/.local/lib/python3.8/site-packages/ray/rllib/evaluation/rollout_worker.py", line 592, in __init__
    check_env(self.env)
  File "/home/mbwie001/.local/lib/python3.8/site-packages/ray/rllib/utils/pre_checks/env.py", line 88, in check_env
    raise ValueError(
ValueError: Traceback (most recent call last):
  File "/home/mbwie001/.local/lib/python3.8/site-packages/ray/rllib/utils/pre_checks/env.py", line 77, in check_env
    check_gym_environments(env)
  File "/home/mbwie001/.local/lib/python3.8/site-packages/ray/rllib/utils/pre_checks/env.py", line 223, in check_gym_environments
    _check_done(done)
  File "/home/mbwie001/.local/lib/python3.8/site-packages/ray/rllib/utils/pre_checks/env.py", line 451, in _check_done
    raise ValueError(error)
ValueError: Your step function must return a done that is a boolean. But instead was a <class 'int'>

The above error has been found in your environment! We've added a module for checking your custom environments. It may cause your experiment to fail if your environment is not set up correctly. You can disable this behavior by setting `disable_env_checking=True` in your environment config dictionary. You can run the environment checking module standalone by calling ray.rllib.utils.check_env([env]).

